12:07:12.439 | [31mERROR[0m   | Task run 'train_task-2b2' - Task run failed with exception: FileNotFoundError('Dataset file not found: data/colon_adata.h5ad') - Retries are exhausted
Traceback (most recent call last):
  File "/workspace/venvc/lib/python3.10/site-packages/prefect/task_engine.py", line 813, in run_context
    yield self
  File "/workspace/venvc/lib/python3.10/site-packages/prefect/task_engine.py", line 1389, in run_task_sync
    engine.call_task_fn(txn)
  File "/workspace/venvc/lib/python3.10/site-packages/prefect/task_engine.py", line 830, in call_task_fn
    result = call_with_parameters(self.task.fn, parameters)
  File "/workspace/venvc/lib/python3.10/site-packages/prefect/utilities/callables.py", line 210, in call_with_parameters
    return fn(*args, **kwargs)
  File "/workspace/scGPT-niche-repo/crohn_wandb.py", line 31, in train_task
    raise FileNotFoundError(f"Dataset file not found: {dataset_path}")
FileNotFoundError: Dataset file not found: data/colon_adata.h5ad
12:07:12.463 | [31mERROR[0m   | Task run 'train_task-2b2' - Finished in state [31mFailed[0m('Task run encountered an exception FileNotFoundError: Dataset file not found: data/colon_adata.h5ad')
12:07:12.464 | [31mERROR[0m   | Flow run[35m 'psychedelic-doberman'[0m - Encountered exception during execution: FileNotFoundError('Dataset file not found: data/colon_adata.h5ad')
Traceback (most recent call last):
  File "/workspace/venvc/lib/python3.10/site-packages/prefect/flow_engine.py", line 763, in run_context
    yield self
  File "/workspace/venvc/lib/python3.10/site-packages/prefect/flow_engine.py", line 1370, in run_flow_sync
    engine.call_flow_fn()
  File "/workspace/venvc/lib/python3.10/site-packages/prefect/flow_engine.py", line 783, in call_flow_fn
    result = call_with_parameters(self.flow.fn, self.parameters)
  File "/workspace/venvc/lib/python3.10/site-packages/prefect/utilities/callables.py", line 210, in call_with_parameters
    return fn(*args, **kwargs)
  File "/workspace/scGPT-niche-repo/crohn_wandb.py", line 143, in main_flow
    ref_embed_adata = train_task(dataset_path, model_path, batch_size).result()
  File "/workspace/venvc/lib/python3.10/site-packages/prefect/tasks.py", line 1063, in __call__
    return run_task(
  File "/workspace/venvc/lib/python3.10/site-packages/prefect/task_engine.py", line 1604, in run_task
    return run_task_sync(**kwargs)
  File "/workspace/venvc/lib/python3.10/site-packages/prefect/task_engine.py", line 1391, in run_task_sync
    return engine.state if return_type == "state" else engine.result()
  File "/workspace/venvc/lib/python3.10/site-packages/prefect/task_engine.py", line 484, in result
    raise self._raised
  File "/workspace/venvc/lib/python3.10/site-packages/prefect/task_engine.py", line 813, in run_context
    yield self
  File "/workspace/venvc/lib/python3.10/site-packages/prefect/task_engine.py", line 1389, in run_task_sync
    engine.call_task_fn(txn)
  File "/workspace/venvc/lib/python3.10/site-packages/prefect/task_engine.py", line 830, in call_task_fn
    result = call_with_parameters(self.task.fn, parameters)
  File "/workspace/venvc/lib/python3.10/site-packages/prefect/utilities/callables.py", line 210, in call_with_parameters
    return fn(*args, **kwargs)
  File "/workspace/scGPT-niche-repo/crohn_wandb.py", line 31, in train_task
    raise FileNotFoundError(f"Dataset file not found: {dataset_path}")
FileNotFoundError: Dataset file not found: data/colon_adata.h5ad
12:07:12.745 | [36mINFO[0m    | Flow run[35m 'psychedelic-doberman'[0m - Finished in state [31mFailed[0m('Flow run encountered an exception: FileNotFoundError: Dataset file not found: data/colon_adata.h5ad')
Traceback (most recent call last):
  File "/workspace/scGPT-niche-repo/crohn_wandb.py", line 163, in <module>
    main_flow(
  File "/workspace/venvc/lib/python3.10/site-packages/prefect/flows.py", line 1671, in __call__
    return run_flow(
  File "/workspace/venvc/lib/python3.10/site-packages/prefect/flow_engine.py", line 1527, in run_flow
    ret_val = run_flow_sync(**kwargs)
  File "/workspace/venvc/lib/python3.10/site-packages/prefect/flow_engine.py", line 1372, in run_flow_sync
    return engine.state if return_type == "state" else engine.result()
  File "/workspace/venvc/lib/python3.10/site-packages/prefect/flow_engine.py", line 350, in result
    raise self._raised
  File "/workspace/venvc/lib/python3.10/site-packages/prefect/flow_engine.py", line 763, in run_context
    yield self
  File "/workspace/venvc/lib/python3.10/site-packages/prefect/flow_engine.py", line 1370, in run_flow_sync
    engine.call_flow_fn()
  File "/workspace/venvc/lib/python3.10/site-packages/prefect/flow_engine.py", line 783, in call_flow_fn
    result = call_with_parameters(self.flow.fn, self.parameters)
  File "/workspace/venvc/lib/python3.10/site-packages/prefect/utilities/callables.py", line 210, in call_with_parameters
    return fn(*args, **kwargs)
  File "/workspace/scGPT-niche-repo/crohn_wandb.py", line 143, in main_flow
    ref_embed_adata = train_task(dataset_path, model_path, batch_size).result()
  File "/workspace/venvc/lib/python3.10/site-packages/prefect/tasks.py", line 1063, in __call__
    return run_task(
  File "/workspace/venvc/lib/python3.10/site-packages/prefect/task_engine.py", line 1604, in run_task
    return run_task_sync(**kwargs)
  File "/workspace/venvc/lib/python3.10/site-packages/prefect/task_engine.py", line 1391, in run_task_sync
    return engine.state if return_type == "state" else engine.result()
  File "/workspace/venvc/lib/python3.10/site-packages/prefect/task_engine.py", line 484, in result
    raise self._raised
  File "/workspace/venvc/lib/python3.10/site-packages/prefect/task_engine.py", line 813, in run_context
    yield self
  File "/workspace/venvc/lib/python3.10/site-packages/prefect/task_engine.py", line 1389, in run_task_sync
    engine.call_task_fn(txn)
  File "/workspace/venvc/lib/python3.10/site-packages/prefect/task_engine.py", line 830, in call_task_fn
    result = call_with_parameters(self.task.fn, parameters)
  File "/workspace/venvc/lib/python3.10/site-packages/prefect/utilities/callables.py", line 210, in call_with_parameters
    return fn(*args, **kwargs)
  File "/workspace/scGPT-niche-repo/crohn_wandb.py", line 31, in train_task
    raise FileNotFoundError(f"Dataset file not found: {dataset_path}")
FileNotFoundError: Dataset file not found: data/colon_adata.h5ad
Traceback (most recent call last):
  File "/workspace/scGPT-niche-repo/crohn_wandb.py", line 163, in <module>
    main_flow(
  File "/workspace/venvc/lib/python3.10/site-packages/prefect/flows.py", line 1671, in __call__
    return run_flow(
  File "/workspace/venvc/lib/python3.10/site-packages/prefect/flow_engine.py", line 1527, in run_flow
    ret_val = run_flow_sync(**kwargs)
  File "/workspace/venvc/lib/python3.10/site-packages/prefect/flow_engine.py", line 1372, in run_flow_sync
    return engine.state if return_type == "state" else engine.result()
  File "/workspace/venvc/lib/python3.10/site-packages/prefect/flow_engine.py", line 350, in result
    raise self._raised
  File "/workspace/venvc/lib/python3.10/site-packages/prefect/flow_engine.py", line 763, in run_context
    yield self
  File "/workspace/venvc/lib/python3.10/site-packages/prefect/flow_engine.py", line 1370, in run_flow_sync
    engine.call_flow_fn()
  File "/workspace/venvc/lib/python3.10/site-packages/prefect/flow_engine.py", line 783, in call_flow_fn
    result = call_with_parameters(self.flow.fn, self.parameters)
  File "/workspace/venvc/lib/python3.10/site-packages/prefect/utilities/callables.py", line 210, in call_with_parameters
    return fn(*args, **kwargs)
  File "/workspace/scGPT-niche-repo/crohn_wandb.py", line 143, in main_flow
    ref_embed_adata = train_task(dataset_path, model_path, batch_size).result()
  File "/workspace/venvc/lib/python3.10/site-packages/prefect/tasks.py", line 1063, in __call__
    return run_task(
  File "/workspace/venvc/lib/python3.10/site-packages/prefect/task_engine.py", line 1604, in run_task
    return run_task_sync(**kwargs)
  File "/workspace/venvc/lib/python3.10/site-packages/prefect/task_engine.py", line 1391, in run_task_sync
    return engine.state if return_type == "state" else engine.result()
  File "/workspace/venvc/lib/python3.10/site-packages/prefect/task_engine.py", line 484, in result
    raise self._raised
  File "/workspace/venvc/lib/python3.10/site-packages/prefect/task_engine.py", line 813, in run_context
    yield self
  File "/workspace/venvc/lib/python3.10/site-packages/prefect/task_engine.py", line 1389, in run_task_sync
    engine.call_task_fn(txn)
  File "/workspace/venvc/lib/python3.10/site-packages/prefect/task_engine.py", line 830, in call_task_fn
    result = call_with_parameters(self.task.fn, parameters)
  File "/workspace/venvc/lib/python3.10/site-packages/prefect/utilities/callables.py", line 210, in call_with_parameters
    return fn(*args, **kwargs)
  File "/workspace/scGPT-niche-repo/crohn_wandb.py", line 31, in train_task
    raise FileNotFoundError(f"Dataset file not found: {dataset_path}")
FileNotFoundError: Dataset file not found: data/colon_adata.h5ad
12:07:13.080 | [93mWARNING[0m | EventsWorker - Still processing items: 3 items remaining...
